PyErr_Format(PyExc_RuntimeError, "unknown data type %d for %s", ds->ds[i].type, value_list.type);